Workbook

Sheet Product Backlog
A1: Pila del producto | G1: Fecha estimada | I1: Fecha real
A2: Incremento | B2: Tarea | C2: Responsable | D2: Estimar HH | E2: Estado | F2: Objetivo del sprint | G2: Inicio | H2: Fin | I2: Inicio | J2: Fin | K2: HH Efectivos
A3: 1 | B3: Determinar entidades y atributos | C3: Sofía Cariñe | D3: 2 | E3: Terminado | F3: Destacar las entidades y atributos. y juntar toda la información | G3: 46142 | H3: 46143 | I3: 46142 | J3: 46143 | K3: 3
A4: 1 | B4: Determinar entidades y atributos | C4: Omar Olmos | D4: 2 | E4: Terminado | F4: Destacar las entidades y atributos. y juntar toda la información | G4: 46142 | H4: 46143 | I4: 46142 | J4: 46143 | K4: 3
A5: 1 | B5: Word incremento 1 | C5: Sofía Cariñe | D5: 15 | E5: Terminado | F5: Realizar la documentacion de todo el incremento 1 | G5: 01-05-2026 | H5: 10-06-2026 | I5: 46143 | J5: 46186 | K5: 25
A6: 1 | B6: Diagrama MERE Boceto | C6: Silvio Villagra | D6: 4.5 | E6: Terminado | F6: Realizar el MERE | G6: 46143 | H6: 46143 | I6: 46143 | J6: 46143 | K6: 8
A7: 1 | B7: Diagrama MERE Boceto | C7: Jhoe Castillo | D7: 2.5 | E7: Terminado | F7: Ordenar el MERE | G7: 46143 | H7: 46143 | I7: 46143 | J7: 46143 | K7: 4
A8: 1 | B8: Revisión de entidades en conjunto | C8: Silvio Villagra | D8: 4 | E8: Terminado | F8: Revisar y comparar las entidades que se comparten con los otros grupos | G8: 46144 | H8: 46144 | I8: 46144 | J8: 46144 | K8: 6
A9: 1 | B9: Corregir documento 0 | C9: Karla Curín | D9: 2 | E9: Terminado | F9: Revisar los errores que encontro el profe y arreglarlos | G9: 46144 | H9: 46145 | I9: 46144 | J9: 46183 | K9: 15
A10: 1 | B10: Corregir documento 0 | C10: Jhoe Castillo | D10: 2 | E10: Terminado | F10: Revisar los errores que encontro el profe y arreglarlos | G10: 46144 | H10: 46145 | I10: 46144 | J10: 46183 | K10: 15
A11: 1 | B11: Diagrama de componentes | C11: Silvio Villagra | D11: 1.5 | E11: Terminado | F11: Realizar diagrama de componentes | G11: 46147 | H11: 46147 | I11: 46147 | J11: 46147 | K11: 3
A12: 1 | B12: Diagrama de componentes | C12: Karla Curín | D12: 1.5 | E12: Terminado | F12: Realizar diagrama de componentes | G12: 46147 | H12: 46147 | I12: 46147 | J12: 46147 | K12: 3
A13: 1 | B13: Diagrama de despliegue | C13: Sofía Cariñe | D13: 1 | E13: Terminado | F13: Realizar diagrama de despliegue | G13: 46147 | H13: 46147 | I13: 46147 | J13: 46147 | K13: 2
A14: 1 | B14: Diagrama de despliegue | C14: Omar Olmos | D14: 1 | E14: Terminado | F14: Realizar diagrama de despliegue | G14: 46147 | H14: 46147 | I14: 46147 | J14: 46147 | K14: 2
A15: 1 | B15: Diagrama de despliegue | C15: Jhoe Castillo | D15: 1 | E15: Terminado | F15: Realizar diagrama de despliegue | G15: 46147 | H15: 46147 | I15: 46147 | J15: 46147 | K15: 2
A16: 1 | B16: Corregir Bizagi | C16: Sofía Cariñe | D16: 1 | E16: Terminado | F16: Arreglar unos errores que encontro el profe | G16: 46149 | H16: 46149 | I16: 46149 | J16: 46149 | K16: 0.5
A17: 1 | B17: Revisión de entidades en conjunto | C17: Silvio Villagra | D17: 4.5 | E17: Terminado | F17: Revisar y comparar las entidades que se comparten con los otros grupos | G17: 46150 | H17: 46150 | I17: 46150 | J17: 46150 | K17: 4.5
... A148: 3 | B148: Pruebas del sistema iteración 1 | C148: Omar Olmos | D148: 5 | E148: Terminado | F148: Realizar las pruebas del sistema de los casos de uso | G148: 46294 | H148: 46297 | I148: 46294 | J148: 46297 | K148: 5

Sheet Graficos Burn I_1
A1: Día | B1: Esfuerzo estimado acumulado [HH] | C1: Esfuerzo real acumulado [HH] | E1: Día | F1: Burndown estimado [HH] | G1: Burndown real [HH]
A2: Dia 0 | B2: 4 | C2: 0 | E2: Dia 0 | F2: 327 | G2: 606.5
A3: Dia 1 | B3: 26 | C3: 24 | E3: Dia 1 | F3: 305 | G3: 582.5
A4: Dia 2 | B4: 34 | C4: 30 | E4: Dia 2 | F4: 297 | G4: 576.5
A5: Dia 3 | B5: 34 | C5: 30 | E5: Dia 3 | F5: 297 | G5: 576.5
A6: Dia 4 | B6: 34 | C6: 30 | E6: Dia 4 | F6: 297 | G6: 576.5
A7: Dia 5 | B7: 40 | C7: 42 | E7: Dia 5 | F7: 291 | G7: 564.5
A8: Dia 6 | B8: 40 | C8: 42 | E8: Dia 6 | F8: 291 | G8: 564.5
A9: Dia 7 | B9: 41 | C9: 42.5 | E9: Dia 7 | F9: 290 | G9: 564
A10: Dia 8 | B10: 50 | C10: 51.5 | E10: Dia 8 | F10: 281 | G10: 555
A11: Dia 9 | B11: 50 | C11: 51.5 | E11: Dia 9 | F11: 281 | G11: 555
A12: Dia 10 | B12: 68 | C12: 69.5 | E12: Dia 10 | F12: 263 | G12: 537
A13: Dia 11 | B13: 73 | C13: 69.5 | E13: Dia 11 | F13: 258 | G13: 537
... A52: Dia 50 | B52: 331 | C52: 606.5 | E52: Dia 50 | F52: 0 | G52: 0

Sheet Graficos Burn I_2
A1: Día | B1: Esfuerzo estimado acumulado [HH] | C1: Esfuerzo real acumulado [HH] | E1: Día | F1: Burndown estimado [HH] | G1: Burndown real [HH]
A2: Día 0 | B2: 0 | C2: 0 | E2: Día 0 | F2: 178 | G2: 201
A3: Día 1 | B3: 2 | C3: 2 | E3: Día 1 | F3: 177 | G3: 201
A4: Día 2 | B4: 4 | C4: 4 | E4: Día 2 | F4: 175 | G4: 198
A5: Día 3 | B5: 6 | C5: 6 | E5: Día 3 | F5: 172 | G5: 195
A6: Día 4 | B6: 6 | C6: 6 | E6: Día 4 | F6: 168 | G6: 190
A7: Día 5 | B7: 6 | C7: 6 | E7: Día 5 | F7: 162 | G7: 182
A8: Día 6 | B8: 6 | C8: 6 | E8: Día 6 | F8: 158 | G8: 175
A9: Día 7 | B9: 24 | C9: 30 | E9: Día 7 | F9: 154 | G9: 168
A10: Día 8 | B10: 24 | C10: 30 | E10: Día 8 | F10: 147 | G10: 160
A11: Día 9 | B11: 24 | C11: 30 | E11: Día 9 | F11: 143 | G11: 154
A12: Día 10 | B12: 24 | C12: 30 | E12: Día 10 | F12: 136 | G12: 143
A13: Día 11 | B13: 47 | C13: 68 | E13: Día 11 | F13: 131 | G13: 133
... A34: Día 32 | B34: 178 | C34: 201 | E34: Día 32 | F34: 0 | G34: 4

Sheet Graficos Burn I_3
A1: Día | B1: Esfuerzo estimado acumulado [HH] | C1: Esfuerzo real acumulado [HH] | E1: Día | F1: Burndown estimado [HH] | G1: Burndown real [HH]
A2: Día 0 | B2: 0 | C2: 0 | E2: Día 0 | F2: 165 | G2: 170
A3: Día 1 | B3: 2 | C3: 2 | E3: Día 1 | F3: 158 | G3: 160
A4: Día 2 | B4: 4 | C4: 4 | E4: Día 2 | F4: 137 | G4: 139
A5: Día 3 | B5: 6 | C5: 6 | E5: Día 3 | F5: 126 | G5: 128
A6: Día 4 | B6: 6 | C6: 6 | E6: Día 4 | F6: 74 | G6: 76
A7: Día 5 | B7: 6 | C7: 6 | E7: Día 5 | F7: 70 | G7: 71
A8: Día 6 | B8: 6 | C8: 6 | E8: Día 6 | F8: 66 | G8: 65
A9: Día 7 | B9: 26 | C9: 28 | E9: Día 7 | F9: 62 | G9: 62
A10: Día 8 | B10: 28 | C10: 28 | E10: Día 8 | F10: 58 | G10: 59
A11: Día 9 | B11: 30 | C11: 33 | E11: Día 9 | F11: 55 | G11: 55
A12: Día 10 | B12: 36 | C12: 36 | E12: Día 10 | F12: 50 | G12: 53
A13: Día 11 | B13: 47 | C13: 46 | E13: Día 11 | F13: 44 | G13: 46
... A23: Día 21 | B23: 165 | C23: 170 | E23: Día 21 | F23: 0 | G23: 0

Sheet Graficos Burn I_t
A1: Día | B1: Esfuerzo estimado acumulado [HH] | C1: Esfuerzo real acumulado [HH] | E1: Día | F1: Burndown estimado [HH] | G1: Burndown real [HH]
A2: Dia 0 | B2: 4 | C2: 0 | E2: Dia 0 | F2: ='Graficos Burn I_3'!F4+F$22 -> 642 | G2: ='Graficos Burn I_3'!G4+G$22 -> 946.5
A3: Dia 1 | B3: 26 | C3: 24 | E3: Dia 1 | F3: ='Graficos Burn I_3'!F5+F$22 -> 631 | G3: ='Graficos Burn I_3'!G5+G$22 -> 935.5
A4: Dia 2 | B4: 34 | C4: 30 | E4: Dia 2 | F4: ='Graficos Burn I_3'!F6+F$22 -> 579 | G4: ='Graficos Burn I_3'!G6+G$22 -> 883.5
A5: Dia 3 | B5: 34 | C5: 30 | E5: Dia 3 | F5: ='Graficos Burn I_3'!F7+F$22 -> 575 | G5: ='Graficos Burn I_3'!G7+G$22 -> 878.5
A6: Dia 4 | B6: 34 | C6: 30 | E6: Dia 4 | F6: ='Graficos Burn I_3'!F8+F$22 -> 571 | G6: ='Graficos Burn I_3'!G8+G$22 -> 872.5
A7: Dia 5 | B7: 40 | C7: 42 | E7: Dia 5 | F7: ='Graficos Burn I_3'!F9+F$22 -> 567 | G7: ='Graficos Burn I_3'!G9+G$22 -> 869.5
A8: Dia 6 | B8: 40 | C8: 42 | E8: Dia 6 | F8: ='Graficos Burn I_3'!F10+F$22 -> 563 | G8: ='Graficos Burn I_3'!G10+G$22 -> 866.5
A9: Dia 7 | B9: 41 | C9: 42.5 | E9: Dia 7 | F9: ='Graficos Burn I_3'!F11+F$22 -> 560 | G9: ='Graficos Burn I_3'!G11+G$22 -> 862.5
A10: Dia 8 | B10: 50 | C10: 51.5 | E10: Dia 8 | F10: ='Graficos Burn I_3'!F12+F$22 -> 555 | G10: ='Graficos Burn I_3'!G12+G$22 -> 860.5
A11: Dia 9 | B11: 50 | C11: 51.5 | E11: Dia 9 | F11: ='Graficos Burn I_3'!F13+F$22 -> 549 | G11: ='Graficos Burn I_3'!G13+G$22 -> 853.5
A12: Dia 10 | B12: 68 | C12: 69.5 | E12: Dia 10 | F12: ='Graficos Burn I_3'!F14+F$22 -> 545 | G12: ='Graficos Burn I_3'!G14+G$22 -> 851.5
A13: Dia 11 | B13: 73 | C13: 69.5 | E13: Dia 11 | F13: ='Graficos Burn I_3'!F15+F$22 -> 540 | G13: ='Graficos Burn I_3'!G15+G$22 -> 844.5
... A21: Dia 19 | B21: 122 | C21: 164.5 | E21: Dia 19 | F21: ='Graficos Burn I_3'!F23+F$22 -> 505 | G21: ='Graficos Burn I_3'!G23+G$22 -> 807.5
A22: Dia 20 | B22: 133 | C22: 165.5 | E22: Dia 20 | F22: ='Graficos Burn I_2'!F2+F$54 -> 505 | G22: ='Graficos Burn I_2'!G2+G$54 -> 807.5
A23: Dia 21 | B23: 145 | C23: 187.5 | E23: Dia 21 | F23: ='Graficos Burn I_2'!F3+F$54 -> 504 | G23: ='Graficos Burn I_2'!G3+G$54 -> 807.5
A24: Dia 22 | B24: 155 | C24: 227.5 | E24: Dia 22 | F24: ='Graficos Burn I_2'!F4+F$54 -> 502 | G24: ='Graficos Burn I_2'!G4+G$54 -> 804.5
A25: Dia 23 | B25: 165 | C25: 258.5 | E25: Dia 23 | F25: ='Graficos Burn I_2'!F5+F$54 -> 499 | G25: ='Graficos Burn I_2'!G5+G$54 -> 801.5
A26: Dia 24 | B26: 165 | C26: 266.5 | E26: Dia 24 | F26: ='Graficos Burn I_2'!F6+F$54 -> 495 | G26: ='Graficos Burn I_2'!G6+G$54 -> 796.5
A27: Dia 25 | B27: 165 | C27: 266.5 | E27: Dia 25 | F27: ='Graficos Burn I_2'!F7+F$54 -> 489 | G27: ='Graficos Burn I_2'!G7+G$54 -> 788.5
A28: Dia 26 | B28: 165 | C28: 266.5 | E28: Dia 26 | F28: ='Graficos Burn I_2'!F8+F$54 -> 485 | G28: ='Graficos Burn I_2'!G8+G$54 -> 781.5
A29: Dia 27 | B29: 171 | C29: 272.5 | E29: Dia 27 | F29: ='Graficos Burn I_2'!F9+F$54 -> 481 | G29: ='Graficos Burn I_2'!G9+G$54 -> 774.5
A30: Dia 28 | B30: 199 | C30: 272.5 | E30: Dia 28 | F30: ='Graficos Burn I_2'!F10+F$54 -> 474 | G30: ='Graficos Burn I_2'!G10+G$54 -> 766.5
A31: Dia 29 | B31: 204 | C31: 272.5 | E31: Dia 29 | F31: ='Graficos Burn I_2'!F11+F$54 -> 470 | G31: ='Graficos Burn I_2'!G11+G$54 -> 760.5
A32: Dia 30 | B32: 204 | C32: 287.5 | E32: Dia 30 | F32: ='Graficos Burn I_2'!F12+F$54 -> 463 | G32: ='Graficos Burn I_2'!G12+G$54 -> 749.5
A33: Dia 31 | B33: 204 | C33: 347.5 | E33: Dia 31 | F33: ='Graficos Burn I_2'!F13+F$54 -> 458 | G33: ='Graficos Burn I_2'!G13+G$54 -> 739.5
... A52: Dia 50 | B52: 331 | C52: 606.5 | E52: Dia 50 | F52: ='Graficos Burn I_2'!F32+F$54 -> 340 | G52: ='Graficos Burn I_2'!G32+G$54 -> 622.5
A53: Dia 51 | B53: ='Graficos Burn I_2'!B2+B$52 -> 331 | C53: ='Graficos Burn I_2'!C2+C$52 -> 606.5 | E53: Dia 51 | F53: ='Graficos Burn I_2'!F33+F$54 -> 331 | G53: ='Graficos Burn I_2'!G33+G$54 -> 612.5
A54: Dia 52 | B54: ='Graficos Burn I_2'!B3+B$52 -> 333 | C54: ='Graficos Burn I_2'!C3+C$52 -> 608.5 | E54: Dia 52 | F54: 327 | G54: 606.5
A55: Dia 53 | B55: ='Graficos Burn I_2'!B4+B$52 -> 335 | C55: ='Graficos Burn I_2'!C4+C$52 -> 610.5 | E55: Dia 53 | F55: 305 | G55: 582.5
A56: Dia 54 | B56: ='Graficos Burn I_2'!B5+B$52 -> 337 | C56: ='Graficos Burn I_2'!C5+C$52 -> 612.5 | E56: Dia 54 | F56: 297 | G56: 576.5
A57: Dia 55 | B57: ='Graficos Burn I_2'!B6+B$52 -> 337 | C57: ='Graficos Burn I_2'!C6+C$52 -> 612.5 | E57: Dia 55 | F57: 297 | G57: 576.5
A58: Dia 56 | B58: ='Graficos Burn I_2'!B7+B$52 -> 337 | C58: ='Graficos Burn I_2'!C7+C$52 -> 612.5 | E58: Dia 56 | F58: 297 | G58: 576.5
A59: Dia 57 | B59: ='Graficos Burn I_2'!B8+B$52 -> 337 | C59: ='Graficos Burn I_2'!C8+C$52 -> 612.5 | E59: Dia 57 | F59: 291 | G59: 564.5
A60: Dia 58 | B60: ='Graficos Burn I_2'!B9+B$52 -> 355 | C60: ='Graficos Burn I_2'!C9+C$52 -> 636.5 | E60: Dia 58 | F60: 291 | G60: 564.5
A61: Dia 59 | B61: ='Graficos Burn I_2'!B10+B$52 -> 355 | C61: ='Graficos Burn I_2'!C10+C$52 -> 636.5 | E61: Dia 59 | F61: 290 | G61: 564
A62: Dia 60 | B62: ='Graficos Burn I_2'!B11+B$52 -> 355 | C62: ='Graficos Burn I_2'!C11+C$52 -> 636.5 | E62: Dia 60 | F62: 281 | G62: 555
A63: Dia 61 | B63: ='Graficos Burn I_2'!B12+B$52 -> 355 | C63: ='Graficos Burn I_2'!C12+C$52 -> 636.5 | E63: Dia 61 | F63: 281 | G63: 555
A64: Dia 62 | B64: ='Graficos Burn I_2'!B13+B$52 -> 378 | C64: ='Graficos Burn I_2'!C13+C$52 -> 674.5 | E64: Dia 62 | F64: 263 | G64: 537
A65: Dia 63 | B65: ='Graficos Burn I_2'!B14+B$52 -> 378 | C65: ='Graficos Burn I_2'!C14+C$52 -> 677.5 | E65: Dia 63 | F65: 258 | G65: 537
...
